<?xml version="1.0"?>
<robot name="kielbasa_robot">
	<!-- Szubienica -->
	<link name="base_link">
		<visual>
			<geometry>
				<mesh filename="szubienica.gltf"/>
			</geometry>
		</visual>
	</link>

	<!-- Kiełbasa 01 -->
	<joint name="joint_01" type="revolute">
		<parent link="base_link"/>
		<child link="kielbasa_01_link"/>
		<origin xyz="0 0 0" rpy="0 0 0"/>
		<axis xyz="0 1 0"/>
		<limit lower="-1.57" upper="1.57" effort="10.0" velocity="1.0"/>
	</joint>
	<link name="kielbasa_01_link">
		<visual>
			<geometry>
				<mesh filename="kielbasa_01.gltf"/>
			</geometry>
		</visual>
	</link>

	<!-- Walec 01 -->
	<joint name="joint_walec_01" type="fixed">
		<parent link="kielbasa_01_link"/>
		<child link="walec_01_link"/>
		<origin xyz="0 0.15 0" rpy="0 0 0"/>
		<!-- Przesunięcie walca między kiełbasy -->
	</joint>
	<link name="walec_01_link">
		<visual>
			<geometry>
				<mesh filename="walec_03.gltf"/>
			</geometry>
		</visual>
	</link>

	<!-- Kiełbasa 02 -->
	<joint name="joint_02" type="revolute">
		<parent link="walec_01_link"/>
		<child link="kielbasa_02_link"/>
		<origin xyz="0 0.15 0" rpy="0 0 0"/>
		<!-- Kiełbasa przesunięta za walec -->
		<axis xyz="0 1 0"/>
		<limit lower="-1.57" upper="1.57" effort="10.0" velocity="1.0"/>
	</joint>
	<link name="kielbasa_02_link">
		<visual>
			<geometry>
				<mesh filename="kielbasa_02.gltf"/>
			</geometry>
		</visual>
	</link>

	<!-- Walec 02 -->
	<joint name="joint_walec_02" type="fixed">
		<parent link="kielbasa_02_link"/>
		<child link="walec_02_link"/>
		<origin xyz="0 0.15 0" rpy="0 0 0"/>
		<!-- Przesunięcie walca między kiełbasy -->
	</joint>
	<link name="walec_02_link">
		<visual>
			<geometry>
				<mesh filename="walec_02.gltf"/>
			</geometry>
		</visual>
	</link>

	<!-- Kiełbasa 03 -->
	<joint name="joint_03" type="revolute">
		<parent link="walec_02_link"/>
		<child link="kielbasa_03_link"/>
		<origin xyz="0 0.15 0" rpy="0 0 0"/>
		<!-- Kiełbasa przesunięta za walec -->
		<axis xyz="0 1 0"/>
		<limit lower="-1.57" upper="1.57" effort="10.0" velocity="1.0"/>
	</joint>
	<link name="kielbasa_03_link">
		<visual>
			<geometry>
				<mesh filename="kielbasa_03.gltf"/>
			</geometry>
		</visual>
	</link>

	<!-- Walec 03 -->
	<joint name="joint_walec_03" type="fixed">
		<parent link="kielbasa_03_link"/>
		<child link="walec_03_link"/>
		<origin xyz="0 0.15 0" rpy="0 0 0"/>
		<!-- Przesunięcie walca między kiełbasy -->
	</joint>
	<link name="walec_03_link">
		<visual>
			<geometry>
				<mesh filename="walec_01.gltf"/>
			</geometry>
		</visual>
	</link>

	<!-- Kiełbasa 04 -->
	<joint name="joint_04" type="revolute">
		<parent link="walec_03_link"/>
		<child link="kielbasa_04_link"/>
		<origin xyz="0 0.15 0" rpy="0 0 0"/>
		<!-- Kiełbasa przesunięta za walec -->
		<axis xyz="0 1 0"/>
		<limit lower="-1.57" upper="1.57" effort="10.0" velocity="1.0"/>
	</joint>
	<link name="kielbasa_04_link">
		<visual>
			<geometry>
				<mesh filename="kielbasa_04.gltf"/>
			</geometry>
		</visual>
	</link>

	<!-- Walec 04 -->
	<joint name="joint_walec_04" type="fixed">
		<parent link="kielbasa_04_link"/>
		<child link="walec_04_link"/>
		<origin xyz="0 0.15 0" rpy="0 0 0"/>
		<!-- Ostatni walec -->
	</joint>
	<link name="walec_04_link">
		<visual>
			<geometry>
				<mesh filename="walec.gltf"/>
			</geometry>
		</visual>
	</link>
</robot>
